def call():
    print("do something")


class Exception1:

    def __init__(self):
        super()

    def do():
        print(f"inner function inside the class with this number ")
